Workbook
Name Slicer_Region: #N/A

Sheet Dashboard
A1: DASHBOARD
M3: Total Return Rate | R3: Customer Satisfaction Score
D11: Region | E11: Total Sales | F11: Total Profit | I11: Category | J11: Total Sales | K11: Total Profit
D12: =Analyze!B4 -> Central | E12: =Analyze!C4 -> 80334.25 | F12: =Analyze!D4 -> 34164.25 | I12: =Analyze!B14 -> Apparel | J12: =Analyze!C14 -> 21509.2 | K12: =Analyze!D14 -> 10159.2
D13: =Analyze!B5 -> Mindanao | E13: =Analyze!C5 -> 66400.38 | F13: =Analyze!D5 -> 26340.38 | I13: =Analyze!B15 -> Electronics | J13: =Analyze!C15 -> 187857.26 | K13: =Analyze!D15 -> 72967.26
D14: =Analyze!B6 -> North | E14: =Analyze!C6 -> 82148.65 | F14: =Analyze!D6 -> 34103.65 | I14: =Analyze!B16 -> Home | J14: =Analyze!C16 -> 33718 | K14: =Analyze!D16 -> 15348
D15: =Analyze!B7 -> South | E15: =Analyze!C7 -> 48793.28 | F15: =Analyze!D7 -> 19793.28 | I15: =Analyze!B17 -> Office Supplies | J15: =Analyze!C17 -> 34592.1 | K15: =Analyze!D17 -> 15927.1
D16: =Analyze!B8 -> Grand Total | E16: =Analyze!C8 -> 277676.56 | F16: =Analyze!D8 -> 114401.56 | I16: =Analyze!B18 -> Grand Total | J16: =Analyze!C18 -> 277676.56 | K16: =Analyze!D18 -> 114401.56
M18: Monthly Sales and Profit FY 2025
D19: Sales and Profit by Region | I19: Sales and Profit by Category

Sheet Analysis
A1: Dashboard Analysis
A2: Business question | B2: Insight | C2: Implication | D2: Suggested Action
A3: How is the business performing overall? | B3: Dashboard shows total sales of 277,677 and profit of 114,402, a 41.2% profit margin. Completed orders are 60%, returned orders 21%, cancelled orders 19%, and average satisfaction is 2.88 / 5. | C3: Profitability is strong, but 40% of orders not completing cleanly and a below-neutral satisfaction score create meaningful leakage risk. | D3: Prioritize reducing returns and cancellations while investigating satisfaction drivers by product, region, and fulfillment step.
A4: Which region leads sales? | B4: North leads with 82,149 sales and 34,104 profit, or 29.6% of total sales. Central is close behind with 80,334 sales and 34,164 profit. | C4: Revenue is concentrated in North and Central, suggesting these markets have the strongest current demand and execution. | D4: Protect stock availability and service levels in North/Central, then replicate their channel or promotion playbook in lower-performing regions.
A5: Which region needs the most attention? | B5: South is the lowest region with 48,793 sales and 19,793 profit, contributing only 17.6% of total sales. | C5: South underperformance limits total growth and may signal weaker demand generation, distribution, or customer fit. | D5: Run a South-region diagnostic on product mix, pricing, promotions, delivery performance, and customer feedback.
A6: Which region has the strongest margin? | B6: Central has the highest margin at 42.5%, followed by North at 41.5%, South at 40.6%, and Mindanao at 39.7%. | C6: Central appears to be the most efficient region, while Mindanao has the most margin improvement room. | D6: Use Central as the operating benchmark and test targeted margin actions in Mindanao.
A7: Which category drives revenue? | B7: Electronics generates 187,857 sales and 72,967 profit, representing 67.7% of total sales. | C7: The business is highly dependent on Electronics, creating concentration risk if demand, inventory, or supplier economics shift. | D7: Maintain Electronics availability and campaigns, but diversify growth into profitable non-Electronics categories.
A8: Which categories offer margin upside? | B8: Apparel has the highest margin at 47.2%, followed by Office Supplies at 46.0% and Home at 45.5%; Electronics margin is lower at 38.8%. | C8: Smaller categories are more profitable, so mix shift can improve profit even without proportional sales growth. | D8: Promote bundles, recommendations, and merchandising that attach Apparel, Office Supplies, and Home to Electronics orders.
A9: What is the strongest month? | B9: May is the best month with 47,321 sales and 19,416 profit, equal to 17.0% of annual sales. | C9: May likely reflects a successful campaign, seasonal lift, or operational peak that can inform repeatable planning. | D9: Investigate May drivers and reuse the strongest promotion, inventory, and channel tactics in future campaigns.
A10: What are the weakest months? | B10: November is the weakest month with 10,717 sales and 5,057 profit; September is also weak with 13,201 sales and 5,581 profit. | C10: Late-year softness or execution gaps create risk to steady sales coverage and resource planning. | D10: Create a September-to-November demand plan with targeted offers, inventory readiness, and weekly conversion tracking.
A11: Is monthly performance consistent? | B11: Monthly sales range from 10,717 in November to 47,321 in May, meaning the best month is about 4.4x the weakest month. | C11: High volatility makes inventory, staffing, and cash planning harder. | D11: Adopt a rolling monthly forecast and trigger review thresholds for months pacing materially below average.
A12: Are order outcomes healthy? | B12: Only 60% of orders are completed, while 21% are returned and 19% are cancelled. | C12: A 40% non-completion rate suggests substantial revenue leakage and possible customer experience issues. | D12: Set a near-term target to lift completed orders above 75% by reducing top cancellation and return causes.
A13: Is customer satisfaction adequate? | B13: Average satisfaction for completed orders is 2.88 / 5, equivalent to 57.7 on a 100-point gauge. | C13: Customer experience is below a healthy benchmark and may be linked to returns, repeat purchase risk, or support burden. | D13: Review low-score orders, survey detractors, and address service, delivery, and product-quality pain points.
A14: What is the highest-priority growth lever? | B14: The clearest opportunity is to improve South-region performance, grow high-margin non-Electronics categories, and reduce order leakage. | C14: These three levers can improve both revenue resilience and profitability without relying only on Electronics growth. | D14: Launch a 90-day action plan with KPIs for South sales, non-Electronics mix, completion rate, return rate, cancellation rate, and satisfaction.

Sheet Transactions
A1: Order ID | B1: Order Date | C1: Customer ID | D1: Product ID | E1: Sales Channel | F1: Payment Method | G1: Quantity | H1: Unit Price | I1: Discount % | J1: Shipping Fee | K1: Gross Sales | L1: Discount Amount | M1: Net Sales | N1: Unit Cost | O1: Total Cost | P1: Profit | Q1: Order Status | R1: Satisfaction Score
A2: ORD-0052 | B2: 45671 | C2: CUST-012 | D2: PROD-003 | E2: Retail | F2: Cash | G2: 2 | H2: 1450 | I2: 0.1 | J2: 0 | K2: 2900 | L2: 290 | M2: 2610 | N2: 850 | O2: 1700 | P2: 910 | Q2: Cancelled | R2: NA
A3: ORD-0078 | B3: 45672 | C3: CUST-002 | D3: PROD-004 | E3: Marketplace | F3: GCash | G3: 5 | H3: 1250 | I3: 0.1 | J3: 100 | K3: 6250 | L3: 625 | M3: 5725 | N3: 700 | O3: 3500 | P3: 2225 | Q3: Returned | R3: 1
A4: ORD-0099 | B4: 45677 | C4: CUST-003 | D4: PROD-011 | E4: Retail | F4: Cash | G4: 8 | H4: 273 | I4: 0.15 | J4: 0 | K4: 2184 | L4: 327.6 | M4: 1856.4 | N4: 130 | O4: 1040 | P4: 816.4 | Q4: Completed | R4: 1
A5: ORD-0083 | B5: 45680 | C5: CUST-011 | D5: PROD-014 | E5: Retail | F5: Cash | G5: 4 | H5: 270 | I5: 0.2 | J5: 100 | K5: 1080 | L5: 216 | M5: 964 | N5: 120 | O5: 480 | P5: 484 | Q5: Completed | R5: 4
A6: ORD-0048 | B6: 45683 | C6: CUST-013 | D6: PROD-010 | E6: Retail | F6: Cash | G6: 1 | H6: 722 | I6: 0.15 | J6: 50 | K6: 722 | L6: 108.3 | M6: 663.7 | N6: 420 | O6: 420 | P6: 243.7 | Q6: Returned | R6: 2
A7: ORD-0025 | B7: 45684 | C7: CUST-020 | D7: PROD-004 | E7: Online Store | F7: Cash | G7: 6 | H7: 1250 | I7: 0.1 | J7: 150 | K7: 7500 | L7: 750 | M7: 6900 | N7: 700 | O7: 4200 | P7: 2700 | Q7: Returned | R7: 3
A8: ORD-0005 | B8: 45690 | C8: CUST-002 | D8: PROD-014 | E8: Reseller | F8: Cash | G8: 2 | H8: 270 | I8: 0.05 | J8: 100 | K8: 540 | L8: 27 | M8: 613 | N8: 120 | O8: 240 | P8: 373 | Q8: Cancelled | R8: NA
A9: ORD-0019 | B9: 45693 | C9: CUST-002 | D9: PROD-001 | E9: Online Store | F9: GCash | G9: 8 | H9: 1650 | I9: 0 | J9: 150 | K9: 13200 | L9: 0 | M9: 13350 | N9: 950 | O9: 7600 | P9: 5750 | Q9: Completed | R9: 2
A10: ORD-0013 | B10: 45706 | C10: CUST-016 | D10: PROD-004 | E10: Online Store | F10: Cash | G10: 3 | H10: 1375 | I10: 0.05 | J10: 100 | K10: 4125 | L10: 206.25 | M10: 4018.75 | N10: 700 | O10: 2100 | P10: 1918.75 | Q10: Returned | R10: 2
A11: ORD-0007 | B11: 45712 | C11: CUST-006 | D11: PROD-008 | E11: Retail | F11: GCash | G11: 1 | H11: 399 | I11: 0.2 | J11: 50 | K11: 399 | L11: 79.8 | M11: 369.2 | N11: 210 | O11: 210 | P11: 159.2 | Q11: Cancelled | R11: NA
A12: ORD-0006 | B12: 45715 | C12: CUST-020 | D12: PROD-008 | E12: Retail | F12: Cash | G12: 5 | H12: 361 | I12: 0 | J12: 150 | K12: 1805 | L12: 0 | M12: 1955 | N12: 210 | O12: 1050 | P12: 905 | Q12: Completed | R12: 3
A13: ORD-0008 | B13: 45715 | C13: CUST-005 | D13: PROD-006 | E13: Retail | F13: Bank Transfer | G13: 3 | H13: 85.5 | I13: 0.2 | J13: 75 | K13: 256.5 | L13: 51.3 | M13: 280.2 | N13: 45 | O13: 135 | P13: 145.2 | Q13: Returned | R13: 1
A14: ORD-0033 | B14: 45717 | C14: CUST-020 | D14: PROD-007 | E14: Reseller | F14: GCash | G14: 6 | H14: 357 | I14: 0.15 | J14: 150 | K14: 2142 | L14: 321.3 | M14: 1970.7 | N14: 180 | O14: 1080 | P14: 890.7 | Q14: Cancelled | R14: NA
A15: ORD-0079 | B15: 45718 | C15: CUST-010 | D15: PROD-009 | E15: Marketplace | F15: Cash | G15: 1 | H15: 187 | I15: 0 | J15: 50 | K15: 187 | L15: 0 | M15: 237 | N15: 90 | O15: 90 | P15: 147 | Q15: Completed | R15: 4
A16: ORD-0097 | B16: 45721 | C16: CUST-018 | D16: PROD-006 | E16: Reseller | F16: Bank Transfer | G16: 2 | H16: 99 | I16: 0 | J16: 75 | K16: 198 | L16: 0 | M16: 273 | N16: 45 | O16: 90 | P16: 183 | Q16: Cancelled | R16: NA
A17: ORD-0009 | B17: 45722 | C17: CUST-008 | D17: PROD-001 | E17: Marketplace | F17: Cash | G17: 4 | H17: 1567.5 | I17: 0 | J17: 100 | K17: 6270 | L17: 0 | M17: 6370 | N17: 950 | O17: 3800 | P17: 2570 | Q17: Completed | R17: 5
A18: ORD-0063 | B18: 45722 | C18: CUST-010 | D18: PROD-004 | E18: Retail | F18: Credit Card | G18: 6 | H18: 1250 | I18: 0.1 | J18: 0 | K18: 7500 | L18: 750 | M18: 6750 | N18: 700 | O18: 4200 | P18: 2550 | Q18: Cancelled | R18: NA
A19: ORD-0004 | B19: 45728 | C19: CUST-018 | D19: PROD-009 | E19: Reseller | F19: Credit Card | G19: 5 | H19: 187 | I19: 0.2 | J19: 100 | K19: 935 | L19: 187 | M19: 848 | N19: 90 | O19: 450 | P19: 398 | Q19: Completed | R19: 2
A20: ORD-0096 | B20: 45730 | C20: CUST-006 | D20: PROD-005 | E20: Marketplace | F20: Cash | G20: 8 | H20: 157.5 | I20: 0.1 | J20: 0 | K20: 1260 | L20: 126 | M20: 1134 | N20: 80 | O20: 640 | P20: 494 | Q20: Returned | R20: 1
A21: ORD-0027 | B21: 45733 | C21: CUST-004 | D21: PROD-002 | E21: Reseller | F21: GCash | G21: 3 | H21: 589 | I21: 0.1 | J21: 150 | K21: 1767 | L21: 176.7 | M21: 1740.3 | N21: 310 | O21: 930 | P21: 810.3 | Q21: Cancelled | R21: NA
A22: ORD-0038 | B22: 45733 | C22: CUST-003 | D22: PROD-005 | E22: Online Store | F22: Credit Card | G22: 6 | H22: 142.5 | I22: 0.05 | J22: 75 | K22: 855 | L22: 42.75 | M22: 887.25 | N22: 80 | O22: 480 | P22: 407.25 | Q22: Completed | R22: 2
A23: ORD-0024 | B23: 45737 | C23: CUST-018 | D23: PROD-005 | E23: Retail | F23: Bank Transfer | G23: 2 | H23: 150 | I23: 0.1 | J23: 0 | K23: 300 | L23: 30 | M23: 270 | N23: 80 | O23: 160 | P23: 110 | Q23: Completed | R23: 5
A24: ORD-0091 | B24: 45759 | C24: CUST-003 | D24: PROD-008 | E24: Reseller | F24: Cash | G24: 6 | H24: 399 | I24: 0.15 | J24: 75 | K24: 2394 | L24: 359.1 | M24: 2109.9 | N24: 210 | O24: 1260 | P24: 849.9 | Q24: Returned | R24: 3
A25: ORD-0051 | B25: 45769 | C25: CUST-020 | D25: PROD-003 | E25: Reseller | F25: Bank Transfer | G25: 4 | H25: 1450 | I25: 0.15 | J25: 0 | K25: 5800 | L25: 870 | M25: 4930 | N25: 850 | O25: 3400 | P25: 1530 | Q25: Cancelled | R25: NA
A26: ORD-0046 | B26: 45770 | C26: CUST-012 | D26: PROD-005 | E26: Reseller | F26: GCash | G26: 7 | H26: 165 | I26: 0.2 | J26: 150 | K26: 1155 | L26: 231 | M26: 1074 | N26: 80 | O26: 560 | P26: 514 | Q26: Cancelled | R26: NA
A27: ORD-0073 | B27: 45775 | C27: CUST-020 | D27: PROD-001 | E27: Online Store | F27: Bank Transfer | G27: 7 | H27: 1732.5 | I27: 0.2 | J27: 75 | K27: 12127.5 | L27: 2425.5 | M27: 9777 | N27: 950 | O27: 6650 | P27: 3127 | Q27: Completed | R27: 1
A28: ORD-0069 | B28: 45776 | C28: CUST-006 | D28: PROD-001 | E28: Retail | F28: Bank Transfer | G28: 7 | H28: 1815 | I28: 0.2 | J28: 100 | K28: 12705 | L28: 2541 | M28: 10264 | N28: 950 | O28: 6650 | P28: 3614 | Q28: Completed | R28: 1
A29: ORD-0068 | B29: 45780 | C29: CUST-020 | D29: PROD-012 | E29: Marketplace | F29: Credit Card | G29: 2 | H29: 300 | I29: 0.05 | J29: 75 | K29: 600 | L29: 30 | M29: 645 | N29: 160 | O29: 320 | P29: 325 | Q29: Completed | R29: 2
A30: ORD-0056 | B30: 45782 | C30: CUST-015 | D30: PROD-007 | E30: Reseller | F30: Cash | G30: 5 | H30: 357 | I30: 0.05 | J30: 0 | K30: 1785 | L30: 89.25 | M30: 1695.75 | N30: 180 | O30: 900 | P30: 795.75 | Q30: Completed | R30: 4
A31: ORD-0001 | B31: 45783 | C31: CUST-007 | D31: PROD-011 | E31: Marketplace | F31: Cash | G31: 5 | H31: 247 | I31: 0.2 | J31: 50 | K31: 1235 | L31: 247 | M31: 1038 | N31: 130 | O31: 650 | P31: 388 | Q31: Cancelled | R31: NA
A32: ORD-0050 | B32: 45784 | C32: CUST-001 | D32: PROD-012 | E32: Marketplace | F32: Credit Card | G32: 1 | H32: 315 | I32: 0.05 | J32: 0 | K32: 315 | L32: 15.75 | M32: 299.25 | N32: 160 | O32: 160 | P32: 139.25 | Q32: Completed | R32: 1
A33: ORD-0015 | B33: 45785 | C33: CUST-007 | D33: PROD-004 | E33: Online Store | F33: Cash | G33: 8 | H33: 1250 | I33: 0.15 | J33: 50 | K33: 10000 | L33: 1500 | M33: 8550 | N33: 700 | O33: 5600 | P33: 2950 | Q33: Completed | R33: 4
A34: ORD-0066 | B34: 45785 | C34: CUST-019 | D34: PROD-011 | E34: Online Store | F34: Cash | G34: 1 | H34: 260 | I34: 0.05 | J34: 150 | K34: 260 | L34: 13 | M34: 397 | N34: 130 | O34: 130 | P34: 267 | Q34: Completed | R34: 1
A35: ORD-0049 | B35: 45787 | C35: CUST-011 | D35: PROD-004 | E35: Online Store | F35: Cash | G35: 8 | H35: 1312.5 | I35: 0.1 | J35: 100 | K35: 10500 | L35: 1050 | M35: 9550 | N35: 700 | O35: 5600 | P35: 3950 | Q35: Completed | R35: 4
A36: ORD-0057 | B36: 45790 | C36: CUST-011 | D36: PROD-001 | E36: Retail | F36: Bank Transfer | G36: 8 | H36: 1732.5 | I36: 0.05 | J36: 100 | K36: 13860 | L36: 693 | M36: 13267 | N36: 950 | O36: 7600 | P36: 5667 | Q36: Completed | R36: 3
A37: ORD-0003 | B37: 45793 | C37: CUST-007 | D37: PROD-015 | E37: Marketplace | F37: GCash | G37: 6 | H37: 900 | I37: 0.15 | J37: 100 | K37: 5400 | L37: 810 | M37: 4690 | N37: 450 | O37: 2700 | P37: 1990 | Q37: Returned | R37: 2
A38: ORD-0022 | B38: 45793 | C38: CUST-001 | D38: PROD-008 | E38: Marketplace | F38: Bank Transfer | G38: 2 | H38: 361 | I38: 0.2 | J38: 50 | K38: 722 | L38: 144.4 | M38: 627.6 | N38: 210 | O38: 420 | P38: 207.6 | Q38: Cancelled | R38: NA
A39: ORD-0032 | B39: 45793 | C39: CUST-018 | D39: PROD-006 | E39: Online Store | F39: Credit Card | G39: 1 | H39: 85.5 | I39: 0.1 | J39: 50 | K39: 85.5 | L39: 8.55 | M39: 126.95 | N39: 45 | O39: 45 | P39: 81.95 | Q39: Cancelled | R39: NA
A40: ORD-0081 | B40: 45794 | C40: CUST-007 | D40: PROD-015 | E40: Online Store | F40: Bank Transfer | G40: 3 | H40: 855 | I40: 0.1 | J40: 100 | K40: 2565 | L40: 256.5 | M40: 2408.5 | N40: 450 | O40: 1350 | P40: 1058.5 | Q40: Completed | R40: 5
...

Sheet Customers
A1: Customer ID | B1: Customer Name | C1: Segment | D1: Region | E1: City | F1: Signup Date
A2: CUST-001 | B2: Customer 01 | C2: Consumer | D2: North | E2: Caloocan | F2: 45208
A3: CUST-002 | B3: Customer 02 | C3: Consumer | D3: South | E3: Makati | F3: 45681
A4: CUST-003 | B4: Customer 03 | C4: Small Business | D4: North | E4: Caloocan | F4: 45485
A5: CUST-004 | B5: Customer 04 | C5: Small Business | D5: North | E5: Manila | F5: 44959
A6: CUST-005 | B6: Customer 05 | C6: Consumer | D6: North | E6: Quezon City | F6: 45165
A7: CUST-006 | B7: Customer 06 | C7: Small Business | D7: North | E7: Quezon City | F7: 45660
A8: CUST-007 | B8: Customer 07 | C8: Consumer | D8: Mindanao | E8: Cagayan de Oro | F8: 45530
A9: CUST-008 | B9: Customer 08 | C9: Consumer | D9: Central | E9: Cebu City | F9: 45641
A10: CUST-009 | B10: Customer 09 | C10: Corporate | D10: Mindanao | E10: Cagayan de Oro | F10: 45086
A11: CUST-010 | B11: Customer 10 | C11: Corporate | D11: South | E11: Makati | F11: 45021
A12: CUST-011 | B12: Customer 11 | C12: Consumer | D12: Mindanao | E12: Cagayan de Oro | F12: 45794
A13: CUST-012 | B13: Customer 12 | C13: Small Business | D13: Central | E13: Mandaue | F13: 45753
... A21: CUST-020 | B21: Customer 20 | C21: Consumer | D21: Central | E21: Mandaue | F21: 45290

Sheet Analyze
B3: Row Labels | C3: Sum of Net Sales | D3: Sum of Profit
B4: Central | C4: 80334.25 | D4: 34164.25 | F4: =B4 -> Central | G4: =C4 -> 80334.25 | H4: =D4 -> 34164.25
B5: Mindanao | C5: 66400.38 | D5: 26340.38 | F5: =B5 -> Mindanao | G5: =C5 -> 66400.38 | H5: =D5 -> 26340.38
B6: North | C6: 82148.65 | D6: 34103.65 | F6: =B6 -> North | G6: =C6 -> 82148.65 | H6: =D6 -> 34103.65
B7: South | C7: 48793.28 | D7: 19793.28 | F7: =B7 -> South | G7: =C7 -> 48793.28 | H7: =D7 -> 19793.28
B8: Grand Total | C8: 277676.56 | D8: 114401.56
B13: Row Labels | C13: Sum of Net Sales | D13: Sum of Profit
B14: Apparel | C14: 21509.2 | D14: 10159.2 | F14: =B14 -> Apparel | G14: =C14 -> 21509.2 | H14: =D14 -> 10159.2
B15: Electronics | C15: 187857.26 | D15: 72967.26 | F15: =B15 -> Electronics | G15: =C15 -> 187857.26 | H15: =D15 -> 72967.26
B16: Home | C16: 33718 | D16: 15348 | F16: =B16 -> Home | G16: =C16 -> 33718 | H16: =D16 -> 15348
B17: Office Supplies | C17: 34592.1 | D17: 15927.1 | F17: =B17 -> Office Supplies | G17: =C17 -> 34592.1 | H17: =D17 -> 15927.1
B18: Grand Total | C18: 277676.56 | D18: 114401.56
B23: Order Date (Month) | C23: Sum of Net Sales | D23: Sum of Profit
B24: Jan | C24: 18719.1 | D24: 7379.1
B25: Feb | C25: 20586.15 | D25: 9251.15
B26: Mar | C26: 20480.25 | D26: 8560.25
B27: Apr | C27: 28154.9 | D27: 9634.9
B28: May | C28: 47321.05 | D28: 19416.05
B29: Jun | C29: 18673.95 | D29: 8333.95
B30: Jul | C30: 31764.25 | D30: 13569.25
B31: Aug | C31: 31500.65 | D31: 12340.65
B32: Sep | C32: 13200.88 | D32: 5580.88
B33: Oct | C33: 23309.98 | D33: 10049.98
B34: Nov | C34: 10717.3 | D34: 5057.3
B35: Dec | C35: 13248.1 | D35: 5228.1
B36: Grand Total | C36: 277676.56 | D36: 114401.56
B40: Row Labels | C40: Count of Order ID
B41: Cancelled | C41: 0.19
B42: Completed | C42: 0.6
B43: Returned | C43: 0.21
B44: Grand Total | C44: 1
C50: Avg. Satisfaction Score | D50: =AVERAGEIF(TransactionsTable[Order Status],"Completed",TransactionsTable[Satisfaction Score]) -> 2.8833333
B53: 0 | C53: Value | D53: =D50*20 -> 57.666667
B54: 0.25 | C54: Pointer | D54: 2
B55: 0.5 | D55: =200-D53-D54 -> 140.33333
B56: 0.25
B57: 1

Sheet Products
A1: Product ID | B1: Product Name | C1: Category | D1: Unit Cost | E1: List Price
A2: PROD-001 | B2: Bluetooth Speaker | C2: Electronics | D2: 950 | E2: 1650
A3: PROD-002 | B3: Wireless Mouse | C3: Electronics | D3: 310 | E3: 620
A4: PROD-003 | B4: USB-C Hub | C4: Electronics | D4: 850 | E4: 1450
A5: PROD-004 | B5: Webcam | C5: Electronics | D5: 700 | E5: 1250
A6: PROD-005 | B6: Notebook Pack | C6: Office Supplies | D6: 80 | E6: 150
A7: PROD-006 | B7: Pen Set | C7: Office Supplies | D7: 45 | E7: 90
A8: PROD-007 | B8: Desk Organizer | C8: Office Supplies | D8: 180 | E8: 340
A9: PROD-008 | B9: Printer Paper | C9: Office Supplies | D9: 210 | E9: 380
A10: PROD-009 | B10: Coffee Mug | C10: Home | D10: 90 | E10: 170
A11: PROD-010 | B11: LED Desk Lamp | C11: Home | D11: 420 | E11: 760
A12: PROD-011 | B12: Storage Box | C12: Home | D12: 130 | E12: 260
A13: PROD-012 | B13: Water Bottle | C13: Home | D13: 160 | E13: 300
... A16: PROD-015 | B16: Hoodie | C16: Apparel | D16: 450 | E16: 900
